ERROR:root:'Username'
Traceback (most recent call last):
  File "C:\Python\Lib\site-packages\pandas\core\indexes\base.py", line 3802, in get_loc
    return self._engine.get_loc(casted_key)
           ^^^^^^^^^^^^^^^^^^^^^^^^^^^^^^^^
  File "pandas\_libs\index.pyx", line 138, in pandas._libs.index.IndexEngine.get_loc
  File "pandas\_libs\index.pyx", line 165, in pandas._libs.index.IndexEngine.get_loc
  File "pandas\_libs\hashtable_class_helper.pxi", line 5745, in pandas._libs.hashtable.PyObjectHashTable.get_item
  File "pandas\_libs\hashtable_class_helper.pxi", line 5753, in pandas._libs.hashtable.PyObjectHashTable.get_item
KeyError: 'Username'

The above exception was the direct cause of the following exception:

Traceback (most recent call last):
  File "d:\Projects\LoanScraper-project\loan.py", line 53, in LoanScraper
    df = get_dataframe_from_gsheet()
         ^^^^^^^^^^^^^^^^^^^^^^^^^^^
  File "d:\Projects\LoanScraper-project\loan.py", line 582, in get_dataframe_from_gsheet
    df = df[df['Username'].notna()]
            ~~^^^^^^^^^^^^
  File "C:\Python\Lib\site-packages\pandas\core\frame.py", line 3807, in __getitem__
    indexer = self.columns.get_loc(key)
              ^^^^^^^^^^^^^^^^^^^^^^^^^
  File "C:\Python\Lib\site-packages\pandas\core\indexes\base.py", line 3804, in get_loc
    raise KeyError(key) from err
KeyError: 'Username'
ERROR:root:module 'gspread_dataframe' has no attribute 'append_rows'
Traceback (most recent call last):
  File "d:\Projects\LoanScraper-project\loan.py", line 245, in LoanScraper
    save_to_google_sheets(df)
  File "d:\Projects\LoanScraper-project\loan.py", line 591, in save_to_google_sheets
    gd.append_rows(new_entry)
    ^^^^^^^^^^^^^^
AttributeError: module 'gspread_dataframe' has no attribute 'append_rows'
